Workbook

Sheet ROI 2025-26
B2: COMPUTATION SHEET OF TAXABLE INCOME & INCOME TAX
A3: Name | B3: : OGS-Facility Management | D3: Asst. Year : 2026-27
A4: Status | B4: : Company
A6: Address | B6: : SY No.7,2nd Main,5th CROSS,GANDHIPURAM,WHITEFIELD, BANGALORE-560066. | D6: FINANCIAL Year : 2025-26
A7: E-mail | D7: PAN : BBUPC0054Q
A8: MobileNo | D8: GSTIN : 29BBUPC0054Q1Z3
A9: ITR Form | B9: : ITR - 4 | D9: Res. Status : Ordinarily Resident
D10: Return Filed : Original
B11: 0
B12: COMPUTATION OF TOTAL INCOME
B13: SOURCES OF INCOME | D13: Amount | E13: Amount | F13: Amount
D14: (Rs) | E14: (Rs) | F14: (Rs)
A16: 1 | B16: INCOME FROM BUSINESS/PROFESSION
B17: 1.1 Business : AIIM FACILITY MANAGEMET SERVICES
B18: Bangalore
B19: Net Profit Before Tax-P1 | C19: : | E19: ='PL 2025-26'!C29 -> 847750
B20: Additions
B21: Depreciation as per Profit and Loss Account | D21: ='PL 2025-26'!C22 -> 232250
B22: TOTAL ADDITIONS U/s.28 TO 44DA | E22: =D21 -> 232250
B23: TOTAL ADDITIONS-P2 | E23: =E22 -> 232250
B25: Depreciation as per Income tax act | C25: : | E25: ='PL 2025-26'!C22 -> 232250
B26: TOTAL DEDUCTIONS-P3 | E26: =E24+E25 -> 232250
B27: Income From Business/Profession(P1+P2-P) | C27: : | E27: =E19+E23-E26 -> 847750
B29: Income From Business/Profession (B1) | C29: : | F29: =E27 -> 847750
A30: 2 | B30: INCOME FROM OTHER SOURCES
B31: 2.1 Interest earned on deposits in saving account with banks, co-operative societies and post office
B32: 1.Interest From bank SB | D32: 25000 | E32: =D32 -> 25000
B34: Income from Other sources | F34: =E32 -> 25000
B36: GROSS TOTAL INCOME | C36: : | F36: =F29+F34 -> 872750
B39: DEDUCTIONS U/c VI A
B40: Description | D40: Gross | E40: Qualifying | F40: Deductable
B41: 80D -Medical Insurance Premium | C41: :
B42: 80D- Total Amount | D42: 0 | E42: 0
B43: 80GG -Deduction in respect of Rent paid | C43: :
B44: Rent Paid(12Months X Rs.10000P.M)=120000 | D44: 0 | E44: 0
B45: 80TTA -Deduction in respect of interest on deposits in savings account. | C45: : | D45: 0 | E45: =D45 -> 0
B47: Total Deductions | F47: =E44+E45 -> 0
B48: TOTAL INCOME | C48: : | F48: =F36-F47 -> 872750
B49: TOTAL INCOME(rounded off) | C49: : | F49: =ROUND(F48,-1) -> 872750
B50: TAX ON TOTAL INCOME | C50: :
...

Sheet PL 2025-26
B3: OGS-Facility Management
B4: SY No.7,2nd Main,5th CROSS,GANDHIPURAM,WHITEFIELD, BANGALORE-560066.
B5: Profit and loss during the year ended 31.03.2026
B6: Particulars | C6: Amount (Rs) | D6: Particulars | E6: Amount (Rs)
B8: To Office Expenses | C8: =20000*12 -> 240000 | D8: By revenue from business | E8: 6150000
B10: " Consultancy Charges | C10: 900000
B12: " Rent paid | C12: =80000*12 -> 960000
B14: " Electricity Paid | C14: =20000*12 -> 240000
B16: " Printing and stationary | C16: =10000*12 -> 120000
B18: " Salaries | C18: =2200000 -> 2200000
B20: " Internet Charges | C20: =5000*12 -> 60000
B22: " Depreciation | C22: ='BS 2025-26'!F10+'BS 2025-26'!F16+'BS 2025-26'!F19 -> 232250
B24: " Repairs and maintenance | C24: =150000 -> 150000
B26: " Miscellaneous Exp | C26: =17000*12-4000 -> 200000
B29: " Net Profit | C29: =ROUND(C32-SUM(C8:C28),0) -> 847750
C32: =E32 -> 6150000 | E32: =SUM(E8:E30) -> 6150000
B38: Place : Bangalore | D38: OGS-Facility Management
B39: Date : | D39: Assessee

Sheet BS 2025-26
B3: OGS-Facility Management
B4: SY No.7,2nd Main,5th CROSS,GANDHIPURAM,WHITEFIELD, BANGALORE-560066.
B5: Balance Sheet as at 31.03.2026
B6: Liabilities | C6: Amount (Rs) | D6: Amount (Rs) | E6: Assets | F6: Amount (Rs) | G6: Amount (Rs)
B8: CAPITAL ACCOUNT | E8: FIXED ASSETS
B9: Balance as on 01.04.2024 | C9: ='[1]BS 2024-25'!$D$14 -> 1131000 | E9: Printer | F9: 50000
B10: Addition during the year | C10: 0 | E10: Less : Depreciation @ 15% | F10: =ROUND(F9*15/100,0) -> 7500 | G10: =ROUND(F9-F10,0) -> 42500
B11: Add: Profit for the year | C11: ='PL 2025-26'!C29 -> 847750 | D11: =C9+C10+C11 -> 1978750
D12: =D11 -> 1978750 | E12: Furniture and Fixtures | F12: 1500000
B13: Less: Drawings | D13: 300000 | E13: Less: Depreciation @ 10% | F13: =ROUND(F12*10/100,0) -> 150000 | G13: =ROUND(F12-F13,0) -> 1350000
D14: =D12-D13 -> 1678750
E15: Vehicle | F15: =125000+1000000 -> 1125000
B16: TRADE RECEIVABLES AND ADVANCES | E16: Less: Depreciation @ 15% | F16: =ROUND(F15*15/100,0) -> 168750 | G16: =ROUND(F15-F16,0) -> 956250
B18: Sundry Creditors | D18: 150000 | E18: laptop | F18: 140000
E19: Less: Depreciation @ 15% | F19: =F18*40/100 -> 56000 | G19: =ROUND(F18-F19,0) -> 84000
B20: Loans and Advances
B21: Bank overdraft. | C21: 1500000 | D21: 1500000 | E21: Sundry debtors | F21: 350000 | G21: =F21 -> 350000
E23: CURRENT ASSETS, LOANS & ADVANCE
E26: Cash In Hand | F26: 34226
E28: Bank Account-HDFC 50200026295042 | F28: =25774.2+52220-21220 -> 56774.2
E30: Rent deposit | F30: 200000 | G30: =F26+F28+F30 -> 291000.2
D35: =SUM(D14:D34) -> 3328750 | G35: =SUM(G10:G34) -> 3073750.2 | I35: =G35-D35 -> -254999.8
B39: Place : Bangalore | E39: OGS-Facility Management
B40: Date : | E40: Asset

Sheet Sheet1
